10/01/2023 06:09:45AM | ERROR | charity.api.events | events.py:14 - No servers found yet, Timeout: 5.0s, Topology Description: <TopologyDescription id: 6518c6d46c5c582f8b09a36f, topology_type: Unknown, servers: [<ServerDescription ('5.35.8.23', 27017) server_type: Unknown, rtt: None>]>
Traceback (most recent call last):
  File "/home/ivan/code/charity/charity/db/db.py", line 97, in check_conn
    await self.motor_client.server_info()
  File "/usr/lib/python3.10/concurrent/futures/thread.py", line 58, in run
    result = self.fn(*self.args, **self.kwargs)
  File "/home/ivan/code/charity/venv/lib/python3.10/site-packages/pymongo/mongo_client.py", line 1805, in server_info
    self.admin.command(
  File "/home/ivan/code/charity/venv/lib/python3.10/site-packages/pymongo/_csot.py", line 105, in csot_wrapper
    return func(self, *args, **kwargs)
  File "/home/ivan/code/charity/venv/lib/python3.10/site-packages/pymongo/database.py", line 805, in command
    with self.__client._socket_for_reads(read_preference, session) as (
  File "/home/ivan/code/charity/venv/lib/python3.10/site-packages/pymongo/mongo_client.py", line 1296, in _socket_for_reads
    server = self._select_server(read_preference, session)
  File "/home/ivan/code/charity/venv/lib/python3.10/site-packages/pymongo/mongo_client.py", line 1257, in _select_server
    server = topology.select_server(server_selector)
  File "/home/ivan/code/charity/venv/lib/python3.10/site-packages/pymongo/topology.py", line 272, in select_server
    server = self._select_server(selector, server_selection_timeout, address)
  File "/home/ivan/code/charity/venv/lib/python3.10/site-packages/pymongo/topology.py", line 261, in _select_server
    servers = self.select_servers(selector, server_selection_timeout, address)
  File "/home/ivan/code/charity/venv/lib/python3.10/site-packages/pymongo/topology.py", line 223, in select_servers
    server_descriptions = self._select_servers_loop(selector, server_timeout, address)
  File "/home/ivan/code/charity/venv/lib/python3.10/site-packages/pymongo/topology.py", line 238, in _select_servers_loop
    raise ServerSelectionTimeoutError(
pymongo.errors.ServerSelectionTimeoutError: No servers found yet, Timeout: 5.0s, Topology Description: <TopologyDescription id: 6518c6d46c5c582f8b09a36f, topology_type: Unknown, servers: [<ServerDescription ('5.35.8.23', 27017) server_type: Unknown, rtt: None>]>

During handling of the above exception, another exception occurred:

Traceback (most recent call last):
  File "/home/ivan/code/charity/charity/api/events.py", line 12, in prepare_db
    await db.check_conn()
  File "/home/ivan/code/charity/charity/db/db.py", line 100, in check_conn
    raise CannotConnectToDb(e)
charity.db.db.CannotConnectToDb: No servers found yet, Timeout: 5.0s, Topology Description: <TopologyDescription id: 6518c6d46c5c582f8b09a36f, topology_type: Unknown, servers: [<ServerDescription ('5.35.8.23', 27017) server_type: Unknown, rtt: None>]>
10/01/2023 06:11:04AM | ERROR | charity.api.events | events.py:14 - No servers found yet, Timeout: 5.0s, Topology Description: <TopologyDescription id: 6518c7220cd2a2376cc5f9a0, topology_type: Unknown, servers: [<ServerDescription ('5.35.8.23', 27017) server_type: Unknown, rtt: None>]>
Traceback (most recent call last):
  File "/home/ivan/code/charity/charity/db/db.py", line 97, in check_conn
    await self.motor_client.server_info()
  File "/usr/lib/python3.10/concurrent/futures/thread.py", line 58, in run
    result = self.fn(*self.args, **self.kwargs)
  File "/home/ivan/code/charity/venv/lib/python3.10/site-packages/pymongo/mongo_client.py", line 1805, in server_info
    self.admin.command(
  File "/home/ivan/code/charity/venv/lib/python3.10/site-packages/pymongo/_csot.py", line 105, in csot_wrapper
    return func(self, *args, **kwargs)
  File "/home/ivan/code/charity/venv/lib/python3.10/site-packages/pymongo/database.py", line 805, in command
    with self.__client._socket_for_reads(read_preference, session) as (
  File "/home/ivan/code/charity/venv/lib/python3.10/site-packages/pymongo/mongo_client.py", line 1296, in _socket_for_reads
    server = self._select_server(read_preference, session)
  File "/home/ivan/code/charity/venv/lib/python3.10/site-packages/pymongo/mongo_client.py", line 1257, in _select_server
    server = topology.select_server(server_selector)
  File "/home/ivan/code/charity/venv/lib/python3.10/site-packages/pymongo/topology.py", line 272, in select_server
    server = self._select_server(selector, server_selection_timeout, address)
  File "/home/ivan/code/charity/venv/lib/python3.10/site-packages/pymongo/topology.py", line 261, in _select_server
    servers = self.select_servers(selector, server_selection_timeout, address)
  File "/home/ivan/code/charity/venv/lib/python3.10/site-packages/pymongo/topology.py", line 223, in select_servers
    server_descriptions = self._select_servers_loop(selector, server_timeout, address)
  File "/home/ivan/code/charity/venv/lib/python3.10/site-packages/pymongo/topology.py", line 238, in _select_servers_loop
    raise ServerSelectionTimeoutError(
pymongo.errors.ServerSelectionTimeoutError: No servers found yet, Timeout: 5.0s, Topology Description: <TopologyDescription id: 6518c7220cd2a2376cc5f9a0, topology_type: Unknown, servers: [<ServerDescription ('5.35.8.23', 27017) server_type: Unknown, rtt: None>]>

During handling of the above exception, another exception occurred:

Traceback (most recent call last):
  File "/home/ivan/code/charity/charity/api/events.py", line 12, in prepare_db
    await db.check_conn()
  File "/home/ivan/code/charity/charity/db/db.py", line 100, in check_conn
    raise CannotConnectToDb(e)
charity.db.db.CannotConnectToDb: No servers found yet, Timeout: 5.0s, Topology Description: <TopologyDescription id: 6518c7220cd2a2376cc5f9a0, topology_type: Unknown, servers: [<ServerDescription ('5.35.8.23', 27017) server_type: Unknown, rtt: None>]>
10/01/2023 06:12:14AM | ERROR | charity.api.events | events.py:14 - No servers found yet, Timeout: 5.0s, Topology Description: <TopologyDescription id: 6518c769f385d8dd7200387b, topology_type: Unknown, servers: [<ServerDescription ('5.35.8.23', 27017) server_type: Unknown, rtt: None>]>
Traceback (most recent call last):
  File "/home/ivan/code/charity/charity/db/db.py", line 97, in check_conn
    await self.motor_client.server_info()
  File "/usr/lib/python3.10/concurrent/futures/thread.py", line 58, in run
    result = self.fn(*self.args, **self.kwargs)
  File "/home/ivan/code/charity/venv/lib/python3.10/site-packages/pymongo/mongo_client.py", line 1805, in server_info
    self.admin.command(
  File "/home/ivan/code/charity/venv/lib/python3.10/site-packages/pymongo/_csot.py", line 105, in csot_wrapper
    return func(self, *args, **kwargs)
  File "/home/ivan/code/charity/venv/lib/python3.10/site-packages/pymongo/database.py", line 805, in command
    with self.__client._socket_for_reads(read_preference, session) as (
  File "/home/ivan/code/charity/venv/lib/python3.10/site-packages/pymongo/mongo_client.py", line 1296, in _socket_for_reads
    server = self._select_server(read_preference, session)
  File "/home/ivan/code/charity/venv/lib/python3.10/site-packages/pymongo/mongo_client.py", line 1257, in _select_server
    server = topology.select_server(server_selector)
  File "/home/ivan/code/charity/venv/lib/python3.10/site-packages/pymongo/topology.py", line 272, in select_server
    server = self._select_server(selector, server_selection_timeout, address)
  File "/home/ivan/code/charity/venv/lib/python3.10/site-packages/pymongo/topology.py", line 261, in _select_server
    servers = self.select_servers(selector, server_selection_timeout, address)
  File "/home/ivan/code/charity/venv/lib/python3.10/site-packages/pymongo/topology.py", line 223, in select_servers
    server_descriptions = self._select_servers_loop(selector, server_timeout, address)
  File "/home/ivan/code/charity/venv/lib/python3.10/site-packages/pymongo/topology.py", line 238, in _select_servers_loop
    raise ServerSelectionTimeoutError(
pymongo.errors.ServerSelectionTimeoutError: No servers found yet, Timeout: 5.0s, Topology Description: <TopologyDescription id: 6518c769f385d8dd7200387b, topology_type: Unknown, servers: [<ServerDescription ('5.35.8.23', 27017) server_type: Unknown, rtt: None>]>

During handling of the above exception, another exception occurred:

Traceback (most recent call last):
  File "/home/ivan/code/charity/charity/api/events.py", line 12, in prepare_db
    await db.check_conn()
  File "/home/ivan/code/charity/charity/db/db.py", line 100, in check_conn
    raise CannotConnectToDb(e)
charity.db.db.CannotConnectToDb: No servers found yet, Timeout: 5.0s, Topology Description: <TopologyDescription id: 6518c769f385d8dd7200387b, topology_type: Unknown, servers: [<ServerDescription ('5.35.8.23', 27017) server_type: Unknown, rtt: None>]>
10/01/2023 06:12:54AM | ERROR | charity.api.events | events.py:14 - No servers found yet, Timeout: 5.0s, Topology Description: <TopologyDescription id: 6518c79182511084c3d3d280, topology_type: Unknown, servers: [<ServerDescription ('5.35.8.23', 27017) server_type: Unknown, rtt: None>]>
Traceback (most recent call last):
  File "/home/ivan/code/charity/charity/db/db.py", line 97, in check_conn
    await self.motor_client.server_info()
  File "/usr/lib/python3.10/concurrent/futures/thread.py", line 58, in run
    result = self.fn(*self.args, **self.kwargs)
  File "/home/ivan/code/charity/venv/lib/python3.10/site-packages/pymongo/mongo_client.py", line 1805, in server_info
    self.admin.command(
  File "/home/ivan/code/charity/venv/lib/python3.10/site-packages/pymongo/_csot.py", line 105, in csot_wrapper
    return func(self, *args, **kwargs)
  File "/home/ivan/code/charity/venv/lib/python3.10/site-packages/pymongo/database.py", line 805, in command
    with self.__client._socket_for_reads(read_preference, session) as (
  File "/home/ivan/code/charity/venv/lib/python3.10/site-packages/pymongo/mongo_client.py", line 1296, in _socket_for_reads
    server = self._select_server(read_preference, session)
  File "/home/ivan/code/charity/venv/lib/python3.10/site-packages/pymongo/mongo_client.py", line 1257, in _select_server
    server = topology.select_server(server_selector)
  File "/home/ivan/code/charity/venv/lib/python3.10/site-packages/pymongo/topology.py", line 272, in select_server
    server = self._select_server(selector, server_selection_timeout, address)
  File "/home/ivan/code/charity/venv/lib/python3.10/site-packages/pymongo/topology.py", line 261, in _select_server
    servers = self.select_servers(selector, server_selection_timeout, address)
  File "/home/ivan/code/charity/venv/lib/python3.10/site-packages/pymongo/topology.py", line 223, in select_servers
    server_descriptions = self._select_servers_loop(selector, server_timeout, address)
  File "/home/ivan/code/charity/venv/lib/python3.10/site-packages/pymongo/topology.py", line 238, in _select_servers_loop
    raise ServerSelectionTimeoutError(
pymongo.errors.ServerSelectionTimeoutError: No servers found yet, Timeout: 5.0s, Topology Description: <TopologyDescription id: 6518c79182511084c3d3d280, topology_type: Unknown, servers: [<ServerDescription ('5.35.8.23', 27017) server_type: Unknown, rtt: None>]>

During handling of the above exception, another exception occurred:

Traceback (most recent call last):
  File "/home/ivan/code/charity/charity/api/events.py", line 12, in prepare_db
    await db.check_conn()
  File "/home/ivan/code/charity/charity/db/db.py", line 100, in check_conn
    raise CannotConnectToDb(e)
charity.db.db.CannotConnectToDb: No servers found yet, Timeout: 5.0s, Topology Description: <TopologyDescription id: 6518c79182511084c3d3d280, topology_type: Unknown, servers: [<ServerDescription ('5.35.8.23', 27017) server_type: Unknown, rtt: None>]>
10/01/2023 06:16:51AM | ERROR | charity.api.events | events.py:14 - No servers found yet, Timeout: 5.0s, Topology Description: <TopologyDescription id: 6518c87d4ca86d1ecff5ab4a, topology_type: Unknown, servers: [<ServerDescription ('5.35.8.23', 27017) server_type: Unknown, rtt: None>]>
Traceback (most recent call last):
  File "/home/ivan/code/charity/charity/db/db.py", line 97, in check_conn
    await self.motor_client.server_info()
  File "/usr/lib/python3.10/concurrent/futures/thread.py", line 58, in run
    result = self.fn(*self.args, **self.kwargs)
  File "/home/ivan/code/charity/venv/lib/python3.10/site-packages/pymongo/mongo_client.py", line 1805, in server_info
    self.admin.command(
  File "/home/ivan/code/charity/venv/lib/python3.10/site-packages/pymongo/_csot.py", line 105, in csot_wrapper
    return func(self, *args, **kwargs)
  File "/home/ivan/code/charity/venv/lib/python3.10/site-packages/pymongo/database.py", line 805, in command
    with self.__client._socket_for_reads(read_preference, session) as (
  File "/home/ivan/code/charity/venv/lib/python3.10/site-packages/pymongo/mongo_client.py", line 1296, in _socket_for_reads
    server = self._select_server(read_preference, session)
  File "/home/ivan/code/charity/venv/lib/python3.10/site-packages/pymongo/mongo_client.py", line 1257, in _select_server
    server = topology.select_server(server_selector)
  File "/home/ivan/code/charity/venv/lib/python3.10/site-packages/pymongo/topology.py", line 272, in select_server
    server = self._select_server(selector, server_selection_timeout, address)
  File "/home/ivan/code/charity/venv/lib/python3.10/site-packages/pymongo/topology.py", line 261, in _select_server
    servers = self.select_servers(selector, server_selection_timeout, address)
  File "/home/ivan/code/charity/venv/lib/python3.10/site-packages/pymongo/topology.py", line 223, in select_servers
    server_descriptions = self._select_servers_loop(selector, server_timeout, address)
  File "/home/ivan/code/charity/venv/lib/python3.10/site-packages/pymongo/topology.py", line 238, in _select_servers_loop
    raise ServerSelectionTimeoutError(
pymongo.errors.ServerSelectionTimeoutError: No servers found yet, Timeout: 5.0s, Topology Description: <TopologyDescription id: 6518c87d4ca86d1ecff5ab4a, topology_type: Unknown, servers: [<ServerDescription ('5.35.8.23', 27017) server_type: Unknown, rtt: None>]>

During handling of the above exception, another exception occurred:

Traceback (most recent call last):
  File "/home/ivan/code/charity/charity/api/events.py", line 12, in prepare_db
    await db.check_conn()
  File "/home/ivan/code/charity/charity/db/db.py", line 100, in check_conn
    raise CannotConnectToDb(e)
charity.db.db.CannotConnectToDb: No servers found yet, Timeout: 5.0s, Topology Description: <TopologyDescription id: 6518c87d4ca86d1ecff5ab4a, topology_type: Unknown, servers: [<ServerDescription ('5.35.8.23', 27017) server_type: Unknown, rtt: None>]>
10/01/2023 06:17:07AM | ERROR | charity.api.events | events.py:14 - No servers found yet, Timeout: 5.0s, Topology Description: <TopologyDescription id: 6518c88e816172fa27a3d17a, topology_type: Unknown, servers: [<ServerDescription ('5.35.8.23', 27017) server_type: Unknown, rtt: None>]>
Traceback (most recent call last):
  File "/home/ivan/code/charity/charity/db/db.py", line 97, in check_conn
    await self.motor_client.server_info()
  File "/usr/lib/python3.10/concurrent/futures/thread.py", line 58, in run
    result = self.fn(*self.args, **self.kwargs)
  File "/home/ivan/code/charity/venv/lib/python3.10/site-packages/pymongo/mongo_client.py", line 1805, in server_info
    self.admin.command(
  File "/home/ivan/code/charity/venv/lib/python3.10/site-packages/pymongo/_csot.py", line 105, in csot_wrapper
    return func(self, *args, **kwargs)
  File "/home/ivan/code/charity/venv/lib/python3.10/site-packages/pymongo/database.py", line 805, in command
    with self.__client._socket_for_reads(read_preference, session) as (
  File "/home/ivan/code/charity/venv/lib/python3.10/site-packages/pymongo/mongo_client.py", line 1296, in _socket_for_reads
    server = self._select_server(read_preference, session)
  File "/home/ivan/code/charity/venv/lib/python3.10/site-packages/pymongo/mongo_client.py", line 1257, in _select_server
    server = topology.select_server(server_selector)
  File "/home/ivan/code/charity/venv/lib/python3.10/site-packages/pymongo/topology.py", line 272, in select_server
    server = self._select_server(selector, server_selection_timeout, address)
  File "/home/ivan/code/charity/venv/lib/python3.10/site-packages/pymongo/topology.py", line 261, in _select_server
    servers = self.select_servers(selector, server_selection_timeout, address)
  File "/home/ivan/code/charity/venv/lib/python3.10/site-packages/pymongo/topology.py", line 223, in select_servers
    server_descriptions = self._select_servers_loop(selector, server_timeout, address)
  File "/home/ivan/code/charity/venv/lib/python3.10/site-packages/pymongo/topology.py", line 238, in _select_servers_loop
    raise ServerSelectionTimeoutError(
pymongo.errors.ServerSelectionTimeoutError: No servers found yet, Timeout: 5.0s, Topology Description: <TopologyDescription id: 6518c88e816172fa27a3d17a, topology_type: Unknown, servers: [<ServerDescription ('5.35.8.23', 27017) server_type: Unknown, rtt: None>]>

During handling of the above exception, another exception occurred:

Traceback (most recent call last):
  File "/home/ivan/code/charity/charity/api/events.py", line 12, in prepare_db
    await db.check_conn()
  File "/home/ivan/code/charity/charity/db/db.py", line 100, in check_conn
    raise CannotConnectToDb(e)
charity.db.db.CannotConnectToDb: No servers found yet, Timeout: 5.0s, Topology Description: <TopologyDescription id: 6518c88e816172fa27a3d17a, topology_type: Unknown, servers: [<ServerDescription ('5.35.8.23', 27017) server_type: Unknown, rtt: None>]>
10/01/2023 06:17:16AM | ERROR | charity.api.events | events.py:14 - No servers found yet, Timeout: 5.0s, Topology Description: <TopologyDescription id: 6518c8967734680ff5564f83, topology_type: Unknown, servers: [<ServerDescription ('5.35.8.23', 27017) server_type: Unknown, rtt: None>]>
Traceback (most recent call last):
  File "/home/ivan/code/charity/charity/db/db.py", line 97, in check_conn
    await self.motor_client.server_info()
  File "/usr/lib/python3.10/concurrent/futures/thread.py", line 58, in run
    result = self.fn(*self.args, **self.kwargs)
  File "/home/ivan/code/charity/venv/lib/python3.10/site-packages/pymongo/mongo_client.py", line 1805, in server_info
    self.admin.command(
  File "/home/ivan/code/charity/venv/lib/python3.10/site-packages/pymongo/_csot.py", line 105, in csot_wrapper
    return func(self, *args, **kwargs)
  File "/home/ivan/code/charity/venv/lib/python3.10/site-packages/pymongo/database.py", line 805, in command
    with self.__client._socket_for_reads(read_preference, session) as (
  File "/home/ivan/code/charity/venv/lib/python3.10/site-packages/pymongo/mongo_client.py", line 1296, in _socket_for_reads
    server = self._select_server(read_preference, session)
  File "/home/ivan/code/charity/venv/lib/python3.10/site-packages/pymongo/mongo_client.py", line 1257, in _select_server
    server = topology.select_server(server_selector)
  File "/home/ivan/code/charity/venv/lib/python3.10/site-packages/pymongo/topology.py", line 272, in select_server
    server = self._select_server(selector, server_selection_timeout, address)
  File "/home/ivan/code/charity/venv/lib/python3.10/site-packages/pymongo/topology.py", line 261, in _select_server
    servers = self.select_servers(selector, server_selection_timeout, address)
  File "/home/ivan/code/charity/venv/lib/python3.10/site-packages/pymongo/topology.py", line 223, in select_servers
    server_descriptions = self._select_servers_loop(selector, server_timeout, address)
  File "/home/ivan/code/charity/venv/lib/python3.10/site-packages/pymongo/topology.py", line 238, in _select_servers_loop
    raise ServerSelectionTimeoutError(
pymongo.errors.ServerSelectionTimeoutError: No servers found yet, Timeout: 5.0s, Topology Description: <TopologyDescription id: 6518c8967734680ff5564f83, topology_type: Unknown, servers: [<ServerDescription ('5.35.8.23', 27017) server_type: Unknown, rtt: None>]>

During handling of the above exception, another exception occurred:

Traceback (most recent call last):
  File "/home/ivan/code/charity/charity/api/events.py", line 12, in prepare_db
    await db.check_conn()
  File "/home/ivan/code/charity/charity/db/db.py", line 100, in check_conn
    raise CannotConnectToDb(e)
charity.db.db.CannotConnectToDb: No servers found yet, Timeout: 5.0s, Topology Description: <TopologyDescription id: 6518c8967734680ff5564f83, topology_type: Unknown, servers: [<ServerDescription ('5.35.8.23', 27017) server_type: Unknown, rtt: None>]>
10/01/2023 06:42:40AM | ERROR | charity.api.events | events.py:14 - No servers found yet, Timeout: 5.0s, Topology Description: <TopologyDescription id: 6518ce8b7a4cef3949bdc271, topology_type: Unknown, servers: [<ServerDescription ('5.35.8.23', 27017) server_type: Unknown, rtt: None>]>
Traceback (most recent call last):
  File "/home/ivan/code/charity/charity/db/db.py", line 97, in check_conn
    await self.motor_client.server_info()
  File "/usr/lib/python3.10/concurrent/futures/thread.py", line 58, in run
    result = self.fn(*self.args, **self.kwargs)
  File "/home/ivan/code/charity/venv/lib/python3.10/site-packages/pymongo/mongo_client.py", line 1805, in server_info
    self.admin.command(
  File "/home/ivan/code/charity/venv/lib/python3.10/site-packages/pymongo/_csot.py", line 105, in csot_wrapper
    return func(self, *args, **kwargs)
  File "/home/ivan/code/charity/venv/lib/python3.10/site-packages/pymongo/database.py", line 805, in command
    with self.__client._socket_for_reads(read_preference, session) as (
  File "/home/ivan/code/charity/venv/lib/python3.10/site-packages/pymongo/mongo_client.py", line 1296, in _socket_for_reads
    server = self._select_server(read_preference, session)
  File "/home/ivan/code/charity/venv/lib/python3.10/site-packages/pymongo/mongo_client.py", line 1257, in _select_server
    server = topology.select_server(server_selector)
  File "/home/ivan/code/charity/venv/lib/python3.10/site-packages/pymongo/topology.py", line 272, in select_server
    server = self._select_server(selector, server_selection_timeout, address)
  File "/home/ivan/code/charity/venv/lib/python3.10/site-packages/pymongo/topology.py", line 261, in _select_server
    servers = self.select_servers(selector, server_selection_timeout, address)
  File "/home/ivan/code/charity/venv/lib/python3.10/site-packages/pymongo/topology.py", line 223, in select_servers
    server_descriptions = self._select_servers_loop(selector, server_timeout, address)
  File "/home/ivan/code/charity/venv/lib/python3.10/site-packages/pymongo/topology.py", line 238, in _select_servers_loop
    raise ServerSelectionTimeoutError(
pymongo.errors.ServerSelectionTimeoutError: No servers found yet, Timeout: 5.0s, Topology Description: <TopologyDescription id: 6518ce8b7a4cef3949bdc271, topology_type: Unknown, servers: [<ServerDescription ('5.35.8.23', 27017) server_type: Unknown, rtt: None>]>

During handling of the above exception, another exception occurred:

Traceback (most recent call last):
  File "/home/ivan/code/charity/charity/api/events.py", line 12, in prepare_db
    await db.check_conn()
  File "/home/ivan/code/charity/charity/db/db.py", line 100, in check_conn
    raise CannotConnectToDb(e)
charity.db.db.CannotConnectToDb: No servers found yet, Timeout: 5.0s, Topology Description: <TopologyDescription id: 6518ce8b7a4cef3949bdc271, topology_type: Unknown, servers: [<ServerDescription ('5.35.8.23', 27017) server_type: Unknown, rtt: None>]>
